Workbook

Sheet Máquinas
A1: Máquinas de Planet Fitness México · catálogo de Mi Progreso 23.0
A2: Llena la columna amarilla "¿Hay en mi club?" con Sí o No (ejemplo en la fila 5). El equipo cambia por sucursal; las cantidades no están confirmadas.
A4: # | B4: Sección | C4: Máquina / equipo | D4: Confianza | E4: Cómo la usa la app | F4: Detalle | G4: Ejercicios de la app que la usan | H4: Equipo que habilita | I4: ¿Hay en mi club? | J4: Notas
A5: 1 | B5: Máquinas de placas (selectorizadas) | C5: Chest press (press de pecho) | D5: Estándar de la cadena | E5: Se usa en tus rutinas salvo que marques No | G5: Chest press (máquina) | I5: Sí | J5: Fila de ejemplo: cámbiala por lo que veas en tu club
A6: 2 | B6: Máquinas de placas (selectorizadas) | C6: Press inclinado (máquina) | D6: Varía por club | E6: Solo se usa si marcas Sí | G6: Press inclinado (máquina)
A7: 3 | B7: Máquinas de placas (selectorizadas) | C7: Pec deck / pectoral fly | D7: Confirmado en México | E7: Se usa en tus rutinas salvo que marques No | F7: 2 en Plaza Satélite; también sirve para deltoide posterior | G7: Pec deck (aperturas en máquina), Aperturas en máquina / polea, Pájaro posterior (reverse pec deck)
A8: 4 | B8: Máquinas de placas (selectorizadas) | C8: Press de hombro | D8: Estándar de la cadena | E8: Se usa en tus rutinas salvo que marques No | G8: Shoulder press (máquina)
A9: 5 | B9: Máquinas de placas (selectorizadas) | C9: Elevaciones laterales (máquina) | D9: Varía por club | E9: Solo se usa si marcas Sí | G9: Elevaciones laterales (máquina)
A10: 6 | B10: Máquinas de placas (selectorizadas) | C10: Jalón al pecho | D10: Estándar de la cadena | E10: Se usa en tus rutinas salvo que marques No | G10: Jalón al pecho
A11: 7 | B11: Máquinas de placas (selectorizadas) | C11: Remo sentado | D11: Estándar de la cadena | E11: Se usa en tus rutinas salvo que marques No | G11: Remo sentado (máquina)
A12: 8 | B12: Máquinas de placas (selectorizadas) | C12: Dominadas y fondos asistidos | D12: Varía por club | E12: Solo se usa si marcas Sí | G12: Dominadas asistidas (máquina), Fondos asistidos (máquina)
A13: 9 | B13: Máquinas de placas (selectorizadas) | C13: Curl de bíceps (máquina) | D13: Estándar de la cadena | E13: Se usa en tus rutinas salvo que marques No | G13: Curl de bíceps (máquina)
A14: 10 | B14: Máquinas de placas (selectorizadas) | C14: Banco predicador | D14: Varía por club | E14: Solo se usa si marcas Sí | G14: Curl predicador
A15: 11 | B15: Máquinas de placas (selectorizadas) | C15: Extensión de tríceps | D15: Estándar de la cadena | E15: Se usa en tus rutinas salvo que marques No | G15: Extensión de tríceps (máquina)
A16: 12 | B16: Máquinas de placas (selectorizadas) | C16: Prensa de pierna | D16: Confirmado en México | E16: Se usa en tus rutinas salvo que marques No | F16: 2 en Plaza Satélite; llegan más en 2026 | G16: Prensa de piernas (máquina), Elevación de talones en prensa
A17: 13 | B17: Máquinas de placas (selectorizadas) | C17: Extensión de pierna | D17: Confirmado en México | E17: Se usa en tus rutinas salvo que marques No | G17: Extensión de cuádriceps
A18: 14 | B18: Máquinas de placas (selectorizadas) | C18: Curl femoral sentado | D18: Estándar de la cadena | E18: Se usa en tus rutinas salvo que marques No | G18: Curl femoral sentado
A19: 15 | B19: Máquinas de placas (selectorizadas) | C19: Curl femoral acostado | D19: Varía por club | E19: Solo se usa si marcas Sí | G19: Curl femoral tumbado
A20: 16 | B20: Máquinas de placas (selectorizadas) | C20: Abductor y aductor | D20: Estándar de la cadena | E20: Se usa en tus rutinas salvo que marques No | G20: Abductor (máquina), Aductor (máquina)
A21: 17 | B21: Máquinas de placas (selectorizadas) | C21: Patada de glúteo (máquina) | D21: No verificado | E21: Solo se usa si marcas Sí | G21: Patada de glúteo (máquina)
A22: 18 | B22: Máquinas de placas (selectorizadas) | C22: Extensión de espalda / hiperextensiones | D22: No verificado | E22: Solo se usa si marcas Sí | G22: Extensión de espalda (máquina), Hiperextensiones
A23: 19 | B23: Máquinas de placas (selectorizadas) | C23: Abdominal (crunch) y rotación | D23: Estándar de la cadena | E23: Se usa en tus rutinas salvo que marques No | G23: Crunch abdominal (máquina), Torso rotation (máquina)
A24: 20 | B24: Máquinas de discos (Matrix Magnum) | C24: Hack squat (Magnum) | D24: Confirmado en México | E24: Se usa en tus rutinas salvo que marques No | F24: Llega en 2026 a 7 clubes de México; estándar en EE. UU. | G24: Hack squat
A25: 21 | B25: Máquinas de discos (Matrix Magnum) | C25: Press de pecho supino (Magnum) | D25: Estándar de la cadena | E25: Se usa en tus rutinas salvo que marques No | F25: En casi todos los clubes de EE. UU. desde 2025 | G25: Press de pecho Magnum (discos)
A26: 22 | B26: Máquinas de discos (Matrix Magnum) | C26: Pantorrilla sentado (Magnum) | D26: Estándar de la cadena | E26: Se usa en tus rutinas salvo que marques No | G26: Elevación de talones sentado
A27: 23 | B27: Máquinas de discos (Matrix Magnum) | C27: Magnum Glute Trainer (hip thrust) | D27: Confirmado en México | E27: Se usa en tus rutinas salvo que marques No | F27: Llega en 2026 a 7 clubes de México | G27: Glute drive Magnum (discos)
A28: 24 | B28: Máquinas de discos (Matrix Magnum) | C28: Prensa de discos 45° | D28: Varía por club | E28: Solo se usa si marcas Sí | G28: Prensa 45°
A29: 25 | B29: Máquinas de discos (Matrix Magnum) | C29: Remo en T (Magnum) | D29: No verificado | E29: Solo se usa si marcas Sí | F29: Matrix lo lanzó en 2025; no hay fuente de que PF lo tenga | G29: Remo en T (Magnum)
A30: 26 | B30: Peso libre, poleas y zona funcional | C30: Máquinas Smith | D30: Confirmado en México | E30: Se usa en tus rutinas salvo que marques No | F30: 6 en Plaza Satélite | H30: Smith
A31: 27 | B31: Peso libre, poleas y zona funcional | C31: Half rack con barra olímpica | D31: Varía por club | E31: Solo se usa si marcas Sí | F31: Anunciado en 2026 para Andamar, El Molino, Center Plazas, San Marcos, Villa Verde, Satélite, Lindavista. Márcalo solo si en tu club hay barra y discos: así la app te deja la sentadilla, el press y el peso muerto con barra. | H31: Barra olímpica
A32: 28 | B32: Peso libre, poleas y zona funcional | C32: Racks de mancuernas | D32: Confirmado en México | E32: Se usa en tus rutinas salvo que marques No | F32: Normalmente de 5 a 75 lb (2 a 34 kg); algunos clubes llegan a 50–60 lb | H32: Mancuernas
A33: 29 | B33: Peso libre, poleas y zona funcional | C33: Bancos planos y ajustables | D33: Confirmado en México | E33: Se usa en tus rutinas salvo que marques No
A34: 30 | B34: Peso libre, poleas y zona funcional | C34: Barras de peso fijo (rectas y EZ, ~20–60 lb) | D34: Estándar de la cadena | E34: Se usa en tus rutinas salvo que marques No | H34: Barra de peso fijo
A35: 31 | B35: Peso libre, poleas y zona funcional | C35: Torres de cable / polea doble ajustable | D35: Estándar de la cadena | E35: Se usa en tus rutinas salvo que marques No | H35: Polea
A36: 32 | B36: Peso libre, poleas y zona funcional | C36: Zona funcional PF 360 (barra para dominadas, TRX, kettlebells) | D36: Estándar de la cadena | E36: Se usa en tus rutinas salvo que marques No | G36: Dominadas / chin-ups, Elevaciones de piernas colgado
A37: 33 | B37: Peso libre, poleas y zona funcional | C37: Paralelas para fondos | D37: No verificado | E37: Solo se usa si marcas Sí | G37: Fondos en paralelas (con lastre)
A38: 34 | B38: Peso libre, poleas y zona funcional | C38: Circuito Express de 30 minutos | D38: Confirmado en México | E38: Se usa en tus rutinas salvo que marques No | F38: 10 máquinas y estaciones de step: 60 s de trabajo y 30 s de descanso
A39: 35 | B39: Cardio | C39: Caminadora Matrix | D39: Confirmado en México | E39: Referencia (cardio / spa) | F39: Marca confirmada; modelo probable Endurance: 0.8–20 km/h, 0–15 %, usuario hasta 182 kg
A40: 36 | B40: Cardio | C40: Elíptica | D40: Confirmado en México | E40: Referencia (cardio / spa)
A41: 37 | B41: Cardio | C41: Bicicleta vertical | D41: Confirmado en México | E41: Referencia (cardio / spa)
...

Sheet Resumen
A1: Resumen del catálogo
A3: Sección | B3: Total | C3: Confirmado en México | D3: Estándar de la cadena | E3: Varía por club | F3: No verificado | G3: Marcadas Sí en mi club | H3: Marcadas No
A4: Máquinas de placas (selectorizadas) | B4: =COUNTIF(Máquinas!$B$5:$B$50,A4) -> 19 | C4: =COUNTIFS(Máquinas!$B$5:$B$50,$A4,Máquinas!$D$5:$D$50,"Confirmado en México") -> 3 | D4: =COUNTIFS(Máquinas!$B$5:$B$50,$A4,Máquinas!$D$5:$D$50,"Estándar de la cadena") -> 9 | E4: =COUNTIFS(Máquinas!$B$5:$B$50,$A4,Máquinas!$D$5:$D$50,"Varía por club") -> 5 | F4: =COUNTIFS(Máquinas!$B$5:$B$50,$A4,Máquinas!$D$5:$D$50,"No verificado") -> 2 | G4: =COUNTIFS(Máquinas!$B$5:$B$50,$A4,Máquinas!$I$5:$I$50,"Sí") -> 1 | H4: =COUNTIFS(Máquinas!$B$5:$B$50,$A4,Máquinas!$I$5:$I$50,"No") -> 0
A5: Máquinas de discos (Matrix Magnum) | B5: =COUNTIF(Máquinas!$B$5:$B$50,A5) -> 6 | C5: =COUNTIFS(Máquinas!$B$5:$B$50,$A5,Máquinas!$D$5:$D$50,"Confirmado en México") -> 2 | D5: =COUNTIFS(Máquinas!$B$5:$B$50,$A5,Máquinas!$D$5:$D$50,"Estándar de la cadena") -> 2 | E5: =COUNTIFS(Máquinas!$B$5:$B$50,$A5,Máquinas!$D$5:$D$50,"Varía por club") -> 1 | F5: =COUNTIFS(Máquinas!$B$5:$B$50,$A5,Máquinas!$D$5:$D$50,"No verificado") -> 1 | G5: =COUNTIFS(Máquinas!$B$5:$B$50,$A5,Máquinas!$I$5:$I$50,"Sí") -> 0 | H5: =COUNTIFS(Máquinas!$B$5:$B$50,$A5,Máquinas!$I$5:$I$50,"No") -> 0
A6: Peso libre, poleas y zona funcional | B6: =COUNTIF(Máquinas!$B$5:$B$50,A6) -> 9 | C6: =COUNTIFS(Máquinas!$B$5:$B$50,$A6,Máquinas!$D$5:$D$50,"Confirmado en México") -> 4 | D6: =COUNTIFS(Máquinas!$B$5:$B$50,$A6,Máquinas!$D$5:$D$50,"Estándar de la cadena") -> 3 | E6: =COUNTIFS(Máquinas!$B$5:$B$50,$A6,Máquinas!$D$5:$D$50,"Varía por club") -> 1 | F6: =COUNTIFS(Máquinas!$B$5:$B$50,$A6,Máquinas!$D$5:$D$50,"No verificado") -> 1 | G6: =COUNTIFS(Máquinas!$B$5:$B$50,$A6,Máquinas!$I$5:$I$50,"Sí") -> 0 | H6: =COUNTIFS(Máquinas!$B$5:$B$50,$A6,Máquinas!$I$5:$I$50,"No") -> 0
A7: Cardio | B7: =COUNTIF(Máquinas!$B$5:$B$50,A7) -> 8 | C7: =COUNTIFS(Máquinas!$B$5:$B$50,$A7,Máquinas!$D$5:$D$50,"Confirmado en México") -> 6 | D7: =COUNTIFS(Máquinas!$B$5:$B$50,$A7,Máquinas!$D$5:$D$50,"Estándar de la cadena") -> 2 | E7: =COUNTIFS(Máquinas!$B$5:$B$50,$A7,Máquinas!$D$5:$D$50,"Varía por club") -> 0 | F7: =COUNTIFS(Máquinas!$B$5:$B$50,$A7,Máquinas!$D$5:$D$50,"No verificado") -> 0 | G7: =COUNTIFS(Máquinas!$B$5:$B$50,$A7,Máquinas!$I$5:$I$50,"Sí") -> 0 | H7: =COUNTIFS(Máquinas!$B$5:$B$50,$A7,Máquinas!$I$5:$I$50,"No") -> 0
A8: Black Card (spa) | B8: =COUNTIF(Máquinas!$B$5:$B$50,A8) -> 4 | C8: =COUNTIFS(Máquinas!$B$5:$B$50,$A8,Máquinas!$D$5:$D$50,"Confirmado en México") -> 4 | D8: =COUNTIFS(Máquinas!$B$5:$B$50,$A8,Máquinas!$D$5:$D$50,"Estándar de la cadena") -> 0 | E8: =COUNTIFS(Máquinas!$B$5:$B$50,$A8,Máquinas!$D$5:$D$50,"Varía por club") -> 0 | F8: =COUNTIFS(Máquinas!$B$5:$B$50,$A8,Máquinas!$D$5:$D$50,"No verificado") -> 0 | G8: =COUNTIFS(Máquinas!$B$5:$B$50,$A8,Máquinas!$I$5:$I$50,"Sí") -> 0 | H8: =COUNTIFS(Máquinas!$B$5:$B$50,$A8,Máquinas!$I$5:$I$50,"No") -> 0
A9: Total | B9: =SUM(B4:B8) -> 46 | C9: =SUM(C4:C8) -> 19 | D9: =SUM(D4:D8) -> 16 | E9: =SUM(E4:E8) -> 7 | F9: =SUM(F4:F8) -> 4 | G9: =SUM(G4:G8) -> 1 | H9: =SUM(H4:H8) -> 0

Sheet Sustitutos en PF
A1: Si tu club no tiene el equipo, la app usa el primer sustituto que sí tengas
A3: Ejercicio original | B3: Sustituto 1 | C3: Sustituto 2 | D3: Sustituto 3
A4: Sentadilla con barra | B4: Hack squat | C4: Sentadilla en Smith | D4: Prensa de piernas (máquina)
A5: Peso muerto | B5: Peso muerto rumano en Smith | C5: Peso muerto rumano
A6: Peso muerto rumano con barra | B6: Peso muerto rumano en Smith | C6: Peso muerto rumano
A7: Press banca con barra | B7: Press de pecho Magnum (discos) | C7: Press banca en Smith | D7: Press banca con mancuernas
A8: Press inclinado con barra | B8: Press inclinado en Smith | C8: Press inclinado con mancuernas | D8: Press inclinado (máquina)
A9: Hammer Strength press | B9: Press de pecho Magnum (discos) | C9: Chest press (máquina)
A10: Remo con barra | B10: Remo en Smith | C10: Remo con mancuerna
A11: Remo en T (Magnum) | B11: Remo con pecho apoyado (mancuernas) | C11: Remo sentado (máquina)
A12: Press militar con barra | B12: Press militar en Smith | C12: Shoulder press (máquina) | D12: Press militar con mancuernas
A13: Zancadas con barra | B13: Zancadas en Smith | C13: Zancadas / split squat búlgaro
A14: Curl con barra de pie | B14: Curl con barra EZ | C14: Curl en polea
A15: Press banca agarre cerrado | B15: Press francés con barra EZ | C15: Extensión de tríceps (máquina)
A16: Puente de glúteo con barra | B16: Glute drive Magnum (discos) | C16: Hip thrust
A17: Hip thrust | B17: Glute drive Magnum (discos)
A18: Dominadas / chin-ups | B18: Dominadas asistidas (máquina) | C18: Jalón al pecho
A19: Fondos en paralelas (con lastre) | B19: Fondos asistidos (máquina) | C19: Extensión de tríceps (máquina)
A20: Prensa 45° | B20: Prensa de piernas (máquina)
A21: Curl femoral tumbado | B21: Curl femoral sentado
A22: Curl predicador | B22: Curl de bíceps (máquina) | C22: Curl con barra EZ
A23: Donkey calf raise | B23: Elevación de talones en prensa | C23: Elevación de talones de pie
A24: Elevación de talones sentado | B24: Elevación de talones en prensa | C24: Elevación de talones de pie
A25: Press inclinado (máquina) | B25: Press inclinado en Smith | C25: Press inclinado con mancuernas
A26: Elevaciones laterales (máquina) | B26: Elevaciones laterales en polea | C26: Elevaciones laterales
A27: Glute drive Magnum (discos) | B27: Hip thrust
A28: Hiperextensiones | B28: Peso muerto rumano | C28: Curl femoral sentado
A29: Pendulum squat | B29: Hack squat | C29: Sentadilla en Smith
A30: Belt squat | B30: Sentadilla en Smith | C30: Prensa de piernas (máquina)
A31: Curl femoral de pie | B31: Curl femoral sentado
A32: Fondos en máquina (sentado) | B32: Fondos asistidos (máquina) | C32: Extensión de tríceps (máquina)
A33: Press JM | B33: Press francés con barra EZ | C33: Extensión de tríceps (máquina)
A34: Remo alto en máquina | B34: Remo sentado (máquina) | C34: Jalón al pecho
A35: Press declinado en máquina | B35: Chest press (máquina) | C35: Press de pecho Magnum (discos)
A36: Pullover en máquina | B36: Pullover en polea (brazos rectos) | C36: Pullover con mancuerna (banco transversal)

Sheet Fuentes
A1: Fuentes y límites
A2: Comunicado PF México 2026 | B2: Equipo nuevo en Andamar, El Molino, Center Plazas, San Marcos, Villa Verde, Satélite, Lindavista: half racks, Smith, prensa, extensión, pec fly, racks de mancuernas, bancos, hack squat, Magnum Glute Trainer (elboletinmexicano.com, gerenciaynegocios.com, almomento.mx)
A3: Comunicado PF enero 2025 | B3: Matrix Magnum: press supino, hack squat y pantorrilla sentado en más de 1,700 clubes (prnewswire.com)
A4: planetfitness.com/our-clubs | B4: Lista general de equipo de los clubes
A5: Informe que compartió el usuario | B5: "Planet Fitness México: caminadoras y catálogo completo de máquinas"
A6: Mancuernas y barras fijas | B6: Rangos de blogs y respuestas de PF (confianza baja a media)
A7: Límite | B7: Las páginas no se pudieron abrir completas; los datos vienen de resúmenes de búsqueda. Confirma en tu sucursal.
A8: Niveles de confianza | B8: Confirmado en México / Estándar de la cadena: la app los usa salvo que marques No. Varía por club / No verificado: solo si marcas Sí.
